Workbook

Sheet Dashboard
B1: Hindivine Healthcare — Admin Dashboard
B2: All figures update automatically from the other sheets. Change the period below.
B4: From | C4: =DATE(YEAR(TODAY()),MONTH(TODAY()),1) -> 46266
B5: To | C5: =EOMONTH(TODAY(),0) -> 46295
B7: Sales Summary | E7: Expenses by Category | F7: Amount (₹)
B8: Total Orders | C8: =COUNTIFS('Injection Sales'!$A$2:$A$501,">="&$C$4,'Injection Sales'!$A$2:$A$501,"<="&$C$5)+COUNTIFS('Protein Sales'!$A$2:$A$501,">="&$C$4,'Protein Sales'!$A$2:$A$501,"<="&$C$5)+COUNTIFS('Diet Support'!$A$2:$A$501,">="&$C$4,'Diet Support'!$A$2:$A$501,"<="&$C$5) -> 3 | E8: =Settings!$I$13 -> Salary | F8: =SUMIFS(Expenses!$C$2:$C$501,Expenses!$B$2:$B$501,E8,Expenses!$A$2:$A$501,">="&$C$4,Expenses!$A$2:$A$501,"<="&$C$5) -> 0
B9: Total Revenue | C9: =SUMIFS('Injection Sales'!$G$2:$G$501,'Injection Sales'!$A$2:$A$501,">="&$C$4,'Injection Sales'!$A$2:$A$501,"<="&$C$5)+SUMIFS('Protein Sales'!$F$2:$F$501,'Protein Sales'!$A$2:$A$501,">="&$C$4,'Protein Sales'!$A$2:$A$501,"<="&$C$5)+SUMIFS('Diet Support'!$E$2:$E$501,'Diet Support'!$A$2:$A$501,">="&$C$4,'Diet Support'!$A$2:$A$501,"<="&$C$5) -> 14000 | E9: =Settings!$I$14 -> Incentive | F9: =SUMIFS(Expenses!$C$2:$C$501,Expenses!$B$2:$B$501,E9,Expenses!$A$2:$A$501,">="&$C$4,Expenses!$A$2:$A$501,"<="&$C$5) -> 0
B10: Total Expenses | C10: =SUMIFS(Expenses!$C$2:$C$501,Expenses!$A$2:$A$501,">="&$C$4,Expenses!$A$2:$A$501,"<="&$C$5) -> 15000 | E10: =Settings!$I$15 -> Rent | F10: =SUMIFS(Expenses!$C$2:$C$501,Expenses!$B$2:$B$501,E10,Expenses!$A$2:$A$501,">="&$C$4,Expenses!$A$2:$A$501,"<="&$C$5) -> 15000
B11: Net Profit | C11: =C9-C10 -> -1000 | E11: =Settings!$I$16 -> Electricity | F11: =SUMIFS(Expenses!$C$2:$C$501,Expenses!$B$2:$B$501,E11,Expenses!$A$2:$A$501,">="&$C$4,Expenses!$A$2:$A$501,"<="&$C$5) -> 0
B12: Total Injection Sales | C12: =SUMIFS('Injection Sales'!$G$2:$G$501,'Injection Sales'!$A$2:$A$501,">="&$C$4,'Injection Sales'!$A$2:$A$501,"<="&$C$5) -> 5000 | E12: =Settings!$I$17 -> Courier | F12: =SUMIFS(Expenses!$C$2:$C$501,Expenses!$B$2:$B$501,E12,Expenses!$A$2:$A$501,">="&$C$4,Expenses!$A$2:$A$501,"<="&$C$5) -> 0
B13: Total Protein Sales | C13: =SUMIFS('Protein Sales'!$F$2:$F$501,'Protein Sales'!$A$2:$A$501,">="&$C$4,'Protein Sales'!$A$2:$A$501,"<="&$C$5) -> 3000 | E13: =Settings!$I$18 -> Marketing | F13: =SUMIFS(Expenses!$C$2:$C$501,Expenses!$B$2:$B$501,E13,Expenses!$A$2:$A$501,">="&$C$4,Expenses!$A$2:$A$501,"<="&$C$5) -> 0
B14: Total Diet Support Sales | C14: =SUMIFS('Diet Support'!$E$2:$E$501,'Diet Support'!$A$2:$A$501,">="&$C$4,'Diet Support'!$A$2:$A$501,"<="&$C$5) -> 6000 | E14: =Settings!$I$19 -> Protein Purchase | F14: =SUMIFS(Expenses!$C$2:$C$501,Expenses!$B$2:$B$501,E14,Expenses!$A$2:$A$501,">="&$C$4,Expenses!$A$2:$A$501,"<="&$C$5) -> 0
E15: =Settings!$I$20 -> Injection Purchase | F15: =SUMIFS(Expenses!$C$2:$C$501,Expenses!$B$2:$B$501,E15,Expenses!$A$2:$A$501,">="&$C$4,Expenses!$A$2:$A$501,"<="&$C$5) -> 0
B16: Patient Summary | E16: =Settings!$I$21 -> Miscellaneous | F16: =SUMIFS(Expenses!$C$2:$C$501,Expenses!$B$2:$B$501,E16,Expenses!$A$2:$A$501,">="&$C$4,Expenses!$A$2:$A$501,"<="&$C$5) -> 0
B17: Total Patients | C17: =COUNTA(Patients!$A$2:$A$501) -> 1 | E17: Total | F17: =SUM(F8:F16) -> 15000
B18: New Patients | C18: =COUNTIFS('Injection Sales'!$A$2:$A$501,">="&$C$4,'Injection Sales'!$A$2:$A$501,"<="&$C$5,'Injection Sales'!$D$2:$D$501,"New") -> 1
B19: Renewal Patients | C19: =COUNTIFS('Injection Sales'!$A$2:$A$501,">="&$C$4,'Injection Sales'!$A$2:$A$501,"<="&$C$5,'Injection Sales'!$D$2:$D$501,"Renewal") -> 0 | E19: Revenue by Type | F19: Amount (₹)
B20: Active Patients | C20: =COUNTIF(Patients!$I$2:$I$501,"Active") -> 1 | E20: Injection | F20: =C12 -> 5000
E21: Protein | F21: =C13 -> 3000
B22: Team Summary | E22: Diet Support | F22: =C14 -> 6000
B23: Total Team Members | C23: =COUNTIFS(Team!$A$2:$A$51,"<>",Team!$G$2:$G$51,"<>Disabled") -> 1
B24: Total Incentives | C24: =Incentives!$E$55 -> 3500
B25: Total Salary (per month) | C25: =SUMIFS(Team!$D$2:$D$51,Team!$G$2:$G$51,"<>Disabled") -> 25000
B26: Top Performer (highest incentive) | C26: =IF(MAX(Incentives!$E$5:$E$54)<=0,"—",INDEX(Incentives!$A$5:$A$54,MATCH(MAX(Incentives!$E$5:$E$54),Incentives!$E$5:$E$54,0))) -> Murshida
B28: Stock Summary (current)
B29: Total Injection Stock | C29: =SUMIFS(Inventory!$H$2:$H$101,Inventory!$A$2:$A$101,"Injection") -> 1
B30: Total Protein Stock | C30: =SUMIFS(Inventory!$H$2:$H$101,Inventory!$A$2:$A$101,"Protein") -> 70
B31: Low Stock Alerts | C31: =COUNTIF(Inventory!$J$2:$J$101,"LOW") -> 14
B32: Needles Stock | C32: =SUMIFS(Inventory!$H$2:$H$101,Inventory!$A$2:$A$101,"Needles") -> 0
B33: Swabs Stock | C33: =SUMIFS(Inventory!$H$2:$H$101,Inventory!$A$2:$A$101,"Alcohol Swabs") -> 0
B34: Syringe Stock | C34: =SUMIFS(Inventory!$H$2:$H$101,Inventory!$A$2:$A$101,"Insulin Syringes") -> 0
B35: Renewal Reminders Due | C35: =COUNTIFS(Renewals!$F$2:$F$501,"*Day",Renewals!$H$2:$H$501,"<>Yes") -> 0

Sheet Patients
A1: Patient Name | B1: Mobile Number | C1: First Purchase | D1: Last Purchase | E1: Orders | F1: Total Spent (₹) | G1: Last Injection Product | H1: Reference Team | I1: Status
A2: Asha Sharma | B2: 9876543210 | C2: =IF(OR(A2="",COUNTIF('Injection Sales'!$B$2:$B$501,A2)+COUNTIF('Protein Sales'!$B$2:$B$501,A2)+COUNTIF('Diet Support'!$B$2:$B$501,A2)=0),"",MIN(IF(COUNTIF('Injection Sales'!$B$2:$B$501,A2),_xlfn.MINIFS('Injection Sales'!$A$2:$A$501,'Injection Sales'!$B$2:$B$501,A2),99999),IF(COUNTIF('Protein Sales'!$B$2:$B$501,A2),_xlfn.MINIFS('Protein Sales'!$A$2:$A$501,'Protein Sales'!$B$2:$B$501,A2),99999),IF(COUNTIF('Diet Support'!$B$2:$B$501,A2),_xlfn.MINIFS('Diet Support'!$A$2:$A$501,'Diet Support'!$B$2:$B$501,A2),99999))) -> 46266 | D2: =IF(OR(A2="",COUNTIF('Injection Sales'!$B$2:$B$501,A2)+COUNTIF('Protein Sales'!$B$2:$B$501,A2)+COUNTIF('Diet Support'!$B$2:$B$501,A2)=0),"",MAX(_xlfn.MAXIFS('Injection Sales'!$A$2:$A$501,'Injection Sales'!$B$2:$B$501,A2),_xlfn.MAXIFS('Protein Sales'!$A$2:$A$501,'Protein Sales'!$B$2:$B$501,A2),_xlfn.MAXIFS('Diet Support'!$A$2:$A$501,'Diet Support'!$B$2:$B$501,A2))) -> 46268 | E2: =IF(A2="","",COUNTIF('Injection Sales'!$B$2:$B$501,A2)+COUNTIF('Protein Sales'!$B$2:$B$501,A2)+COUNTIF('Diet Support'!$B$2:$B$501,A2)) -> 3 | F2: =IF(A2="","",SUMIF('Injection Sales'!$B$2:$B$501,A2,'Injection Sales'!$G$2:$G$501)+SUMIF('Protein Sales'!$B$2:$B$501,A2,'Protein Sales'!$F$2:$F$501)+SUMIF('Diet Support'!$B$2:$B$501,A2,'Diet Support'!$E$2:$E$501)) -> 14000 | G2: =IF(OR(A2="",COUNTIF('Injection Sales'!$B$2:$B$501,A2)=0),"",IFERROR(LOOKUP(2,1/(('Injection Sales'!$B$2:$B$501=A2)*('Injection Sales'!$A$2:$A$501=_xlfn.MAXIFS('Injection Sales'!$A$2:$A$501,'Injection Sales'!$B$2:$B$501,A2))),'Injection Sales'!$E$2:$E$501),"")) -> Mounjaro 5mg | H2: =IF(OR(A2="",COUNTIF('Injection Sales'!$B$2:$B$501,A2)=0),"",IFERROR(LOOKUP(2,1/(('Injection Sales'!$B$2:$B$501=A2)*('Injection Sales'!$A$2:$A$501=_xlfn.MAXIFS('Injection Sales'!$A$2:$A$501,'Injection Sales'!$B$2:$B$501,A2))),'Injection Sales'!$H$2:$H$501),"")) -> Murshida | I2: =IF(OR(A2="",D2=""),"",IF(TODAY()-D2<=Settings!$B$7,"Active","Inactive")) -> Active
C3: =IF(OR(A3="",COUNTIF('Injection Sales'!$B$2:$B$501,A3)+COUNTIF('Protein Sales'!$B$2:$B$501,A3)+COUNTIF('Diet Support'!$B$2:$B$501,A3)=0),"",MIN(IF(COUNTIF('Injection Sales'!$B$2:$B$501,A3),_xlfn.MINIFS('Injection Sales'!$A$2:$A$501,'Injection Sales'!$B$2:$B$501,A3),99999),IF(COUNTIF('Protein Sales'!$B$2:$B$501,A3),_xlfn.MINIFS('Protein Sales'!$A$2:$A$501,'Protein Sales'!$B$2:$B$501,A3),99999),IF(COUNTIF('Diet Support'!$B$2:$B$501,A3),_xlfn.MINIFS('Diet Support'!$A$2:$A$501,'Diet Support'!$B$2:$B$501,A3),99999))) | D3: =IF(OR(A3="",COUNTIF('Injection Sales'!$B$2:$B$501,A3)+COUNTIF('Protein Sales'!$B$2:$B$501,A3)+COUNTIF('Diet Support'!$B$2:$B$501,A3)=0),"",MAX(_xlfn.MAXIFS('Injection Sales'!$A$2:$A$501,'Injection Sales'!$B$2:$B$501,A3),_xlfn.MAXIFS('Protein Sales'!$A$2:$A$501,'Protein Sales'!$B$2:$B$501,A3),_xlfn.MAXIFS('Diet Support'!$A$2:$A$501,'Diet Support'!$B$2:$B$501,A3))) | E3: =IF(A3="","",COUNTIF('Injection Sales'!$B$2:$B$501,A3)+COUNTIF('Protein Sales'!$B$2:$B$501,A3)+COUNTIF('Diet Support'!$B$2:$B$501,A3)) | F3: =IF(A3="","",SUMIF('Injection Sales'!$B$2:$B$501,A3,'Injection Sales'!$G$2:$G$501)+SUMIF('Protein Sales'!$B$2:$B$501,A3,'Protein Sales'!$F$2:$F$501)+SUMIF('Diet Support'!$B$2:$B$501,A3,'Diet Support'!$E$2:$E$501)) | G3: =IF(OR(A3="",COUNTIF('Injection Sales'!$B$2:$B$501,A3)=0),"",IFERROR(LOOKUP(2,1/(('Injection Sales'!$B$2:$B$501=A3)*('Injection Sales'!$A$2:$A$501=_xlfn.MAXIFS('Injection Sales'!$A$2:$A$501,'Injection Sales'!$B$2:$B$501,A3))),'Injection Sales'!$E$2:$E$501),"")) | H3: =IF(OR(A3="",COUNTIF('Injection Sales'!$B$2:$B$501,A3)=0),"",IFERROR(LOOKUP(2,1/(('Injection Sales'!$B$2:$B$501=A3)*('Injection Sales'!$A$2:$A$501=_xlfn.MAXIFS('Injection Sales'!$A$2:$A$501,'Injection Sales'!$B$2:$B$501,A3))),'Injection Sales'!$H$2:$H$501),"")) | I3: =IF(OR(A3="",D3=""),"",IF(TODAY()-D3<=Settings!$B$7,"Active","Inactive"))
C4: =IF(OR(A4="",COUNTIF('Injection Sales'!$B$2:$B$501,A4)+COUNTIF('Protein Sales'!$B$2:$B$501,A4)+COUNTIF('Diet Support'!$B$2:$B$501,A4)=0),"",MIN(IF(COUNTIF('Injection Sales'!$B$2:$B$501,A4),_xlfn.MINIFS('Injection Sales'!$A$2:$A$501,'Injection Sales'!$B$2:$B$501,A4),99999),IF(COUNTIF('Protein Sales'!$B$2:$B$501,A4),_xlfn.MINIFS('Protein Sales'!$A$2:$A$501,'Protein Sales'!$B$2:$B$501,A4),99999),IF(COUNTIF('Diet Support'!$B$2:$B$501,A4),_xlfn.MINIFS('Diet Support'!$A$2:$A$501,'Diet Support'!$B$2:$B$501,A4),99999))) | D4: =IF(OR(A4="",COUNTIF('Injection Sales'!$B$2:$B$501,A4)+COUNTIF('Protein Sales'!$B$2:$B$501,A4)+COUNTIF('Diet Support'!$B$2:$B$501,A4)=0),"",MAX(_xlfn.MAXIFS('Injection Sales'!$A$2:$A$501,'Injection Sales'!$B$2:$B$501,A4),_xlfn.MAXIFS('Protein Sales'!$A$2:$A$501,'Protein Sales'!$B$2:$B$501,A4),_xlfn.MAXIFS('Diet Support'!$A$2:$A$501,'Diet Support'!$B$2:$B$501,A4))) | E4: =IF(A4="","",COUNTIF('Injection Sales'!$B$2:$B$501,A4)+COUNTIF('Protein Sales'!$B$2:$B$501,A4)+COUNTIF('Diet Support'!$B$2:$B$501,A4)) | F4: =IF(A4="","",SUMIF('Injection Sales'!$B$2:$B$501,A4,'Injection Sales'!$G$2:$G$501)+SUMIF('Protein Sales'!$B$2:$B$501,A4,'Protein Sales'!$F$2:$F$501)+SUMIF('Diet Support'!$B$2:$B$501,A4,'Diet Support'!$E$2:$E$501)) | G4: =IF(OR(A4="",COUNTIF('Injection Sales'!$B$2:$B$501,A4)=0),"",IFERROR(LOOKUP(2,1/(('Injection Sales'!$B$2:$B$501=A4)*('Injection Sales'!$A$2:$A$501=_xlfn.MAXIFS('Injection Sales'!$A$2:$A$501,'Injection Sales'!$B$2:$B$501,A4))),'Injection Sales'!$E$2:$E$501),"")) | H4: =IF(OR(A4="",COUNTIF('Injection Sales'!$B$2:$B$501,A4)=0),"",IFERROR(LOOKUP(2,1/(('Injection Sales'!$B$2:$B$501=A4)*('Injection Sales'!$A$2:$A$501=_xlfn.MAXIFS('Injection Sales'!$A$2:$A$501,'Injection Sales'!$B$2:$B$501,A4))),'Injection Sales'!$H$2:$H$501),"")) | I4: =IF(OR(A4="",D4=""),"",IF(TODAY()-D4<=Settings!$B$7,"Active","Inactive"))
C5: =IF(OR(A5="",COUNTIF('Injection Sales'!$B$2:$B$501,A5)+COUNTIF('Protein Sales'!$B$2:$B$501,A5)+COUNTIF('Diet Support'!$B$2:$B$501,A5)=0),"",MIN(IF(COUNTIF('Injection Sales'!$B$2:$B$501,A5),_xlfn.MINIFS('Injection Sales'!$A$2:$A$501,'Injection Sales'!$B$2:$B$501,A5),99999),IF(COUNTIF('Protein Sales'!$B$2:$B$501,A5),_xlfn.MINIFS('Protein Sales'!$A$2:$A$501,'Protein Sales'!$B$2:$B$501,A5),99999),IF(COUNTIF('Diet Support'!$B$2:$B$501,A5),_xlfn.MINIFS('Diet Support'!$A$2:$A$501,'Diet Support'!$B$2:$B$501,A5),99999))) | D5: =IF(OR(A5="",COUNTIF('Injection Sales'!$B$2:$B$501,A5)+COUNTIF('Protein Sales'!$B$2:$B$501,A5)+COUNTIF('Diet Support'!$B$2:$B$501,A5)=0),"",MAX(_xlfn.MAXIFS('Injection Sales'!$A$2:$A$501,'Injection Sales'!$B$2:$B$501,A5),_xlfn.MAXIFS('Protein Sales'!$A$2:$A$501,'Protein Sales'!$B$2:$B$501,A5),_xlfn.MAXIFS('Diet Support'!$A$2:$A$501,'Diet Support'!$B$2:$B$501,A5))) | E5: =IF(A5="","",COUNTIF('Injection Sales'!$B$2:$B$501,A5)+COUNTIF('Protein Sales'!$B$2:$B$501,A5)+COUNTIF('Diet Support'!$B$2:$B$501,A5)) | F5: =IF(A5="","",SUMIF('Injection Sales'!$B$2:$B$501,A5,'Injection Sales'!$G$2:$G$501)+SUMIF('Protein Sales'!$B$2:$B$501,A5,'Protein Sales'!$F$2:$F$501)+SUMIF('Diet Support'!$B$2:$B$501,A5,'Diet Support'!$E$2:$E$501)) | G5: =IF(OR(A5="",COUNTIF('Injection Sales'!$B$2:$B$501,A5)=0),"",IFERROR(LOOKUP(2,1/(('Injection Sales'!$B$2:$B$501=A5)*('Injection Sales'!$A$2:$A$501=_xlfn.MAXIFS('Injection Sales'!$A$2:$A$501,'Injection Sales'!$B$2:$B$501,A5))),'Injection Sales'!$E$2:$E$501),"")) | H5: =IF(OR(A5="",COUNTIF('Injection Sales'!$B$2:$B$501,A5)=0),"",IFERROR(LOOKUP(2,1/(('Injection Sales'!$B$2:$B$501=A5)*('Injection Sales'!$A$2:$A$501=_xlfn.MAXIFS('Injection Sales'!$A$2:$A$501,'Injection Sales'!$B$2:$B$501,A5))),'Injection Sales'!$H$2:$H$501),"")) | I5: =IF(OR(A5="",D5=""),"",IF(TODAY()-D5<=Settings!$B$7,"Active","Inactive"))
C6: =IF(OR(A6="",COUNTIF('Injection Sales'!$B$2:$B$501,A6)+COUNTIF('Protein Sales'!$B$2:$B$501,A6)+COUNTIF('Diet Support'!$B$2:$B$501,A6)=0),"",MIN(IF(COUNTIF('Injection Sales'!$B$2:$B$501,A6),_xlfn.MINIFS('Injection Sales'!$A$2:$A$501,'Injection Sales'!$B$2:$B$501,A6),99999),IF(COUNTIF('Protein Sales'!$B$2:$B$501,A6),_xlfn.MINIFS('Protein Sales'!$A$2:$A$501,'Protein Sales'!$B$2:$B$501,A6),99999),IF(COUNTIF('Diet Support'!$B$2:$B$501,A6),_xlfn.MINIFS('Diet Support'!$A$2:$A$501,'Diet Support'!$B$2:$B$501,A6),99999))) | D6: =IF(OR(A6="",COUNTIF('Injection Sales'!$B$2:$B$501,A6)+COUNTIF('Protein Sales'!$B$2:$B$501,A6)+COUNTIF('Diet Support'!$B$2:$B$501,A6)=0),"",MAX(_xlfn.MAXIFS('Injection Sales'!$A$2:$A$501,'Injection Sales'!$B$2:$B$501,A6),_xlfn.MAXIFS('Protein Sales'!$A$2:$A$501,'Protein Sales'!$B$2:$B$501,A6),_xlfn.MAXIFS('Diet Support'!$A$2:$A$501,'Diet Support'!$B$2:$B$501,A6))) | E6: =IF(A6="","",COUNTIF('Injection Sales'!$B$2:$B$501,A6)+COUNTIF('Protein Sales'!$B$2:$B$501,A6)+COUNTIF('Diet Support'!$B$2:$B$501,A6)) | F6: =IF(A6="","",SUMIF('Injection Sales'!$B$2:$B$501,A6,'Injection Sales'!$G$2:$G$501)+SUMIF('Protein Sales'!$B$2:$B$501,A6,'Protein Sales'!$F$2:$F$501)+SUMIF('Diet Support'!$B$2:$B$501,A6,'Diet Support'!$E$2:$E$501)) | G6: =IF(OR(A6="",COUNTIF('Injection Sales'!$B$2:$B$501,A6)=0),"",IFERROR(LOOKUP(2,1/(('Injection Sales'!$B$2:$B$501=A6)*('Injection Sales'!$A$2:$A$501=_xlfn.MAXIFS('Injection Sales'!$A$2:$A$501,'Injection Sales'!$B$2:$B$501,A6))),'Injection Sales'!$E$2:$E$501),"")) | H6: =IF(OR(A6="",COUNTIF('Injection Sales'!$B$2:$B$501,A6)=0),"",IFERROR(LOOKUP(2,1/(('Injection Sales'!$B$2:$B$501=A6)*('Injection Sales'!$A$2:$A$501=_xlfn.MAXIFS('Injection Sales'!$A$2:$A$501,'Injection Sales'!$B$2:$B$501,A6))),'Injection Sales'!$H$2:$H$501),"")) | I6: =IF(OR(A6="",D6=""),"",IF(TODAY()-D6<=Settings!$B$7,"Active","Inactive"))
C7: =IF(OR(A7="",COUNTIF('Injection Sales'!$B$2:$B$501,A7)+COUNTIF('Protein Sales'!$B$2:$B$501,A7)+COUNTIF('Diet Support'!$B$2:$B$501,A7)=0),"",MIN(IF(COUNTIF('Injection Sales'!$B$2:$B$501,A7),_xlfn.MINIFS('Injection Sales'!$A$2:$A$501,'Injection Sales'!$B$2:$B$501,A7),99999),IF(COUNTIF('Protein Sales'!$B$2:$B$501,A7),_xlfn.MINIFS('Protein Sales'!$A$2:$A$501,'Protein Sales'!$B$2:$B$501,A7),99999),IF(COUNTIF('Diet Support'!$B$2:$B$501,A7),_xlfn.MINIFS('Diet Support'!$A$2:$A$501,'Diet Support'!$B$2:$B$501,A7),99999))) | D7: =IF(OR(A7="",COUNTIF('Injection Sales'!$B$2:$B$501,A7)+COUNTIF('Protein Sales'!$B$2:$B$501,A7)+COUNTIF('Diet Support'!$B$2:$B$501,A7)=0),"",MAX(_xlfn.MAXIFS('Injection Sales'!$A$2:$A$501,'Injection Sales'!$B$2:$B$501,A7),_xlfn.MAXIFS('Protein Sales'!$A$2:$A$501,'Protein Sales'!$B$2:$B$501,A7),_xlfn.MAXIFS('Diet Support'!$A$2:$A$501,'Diet Support'!$B$2:$B$501,A7))) | E7: =IF(A7="","",COUNTIF('Injection Sales'!$B$2:$B$501,A7)+COUNTIF('Protein Sales'!$B$2:$B$501,A7)+COUNTIF('Diet Support'!$B$2:$B$501,A7)) | F7: =IF(A7="","",SUMIF('Injection Sales'!$B$2:$B$501,A7,'Injection Sales'!$G$2:$G$501)+SUMIF('Protein Sales'!$B$2:$B$501,A7,'Protein Sales'!$F$2:$F$501)+SUMIF('Diet Support'!$B$2:$B$501,A7,'Diet Support'!$E$2:$E$501)) | G7: =IF(OR(A7="",COUNTIF('Injection Sales'!$B$2:$B$501,A7)=0),"",IFERROR(LOOKUP(2,1/(('Injection Sales'!$B$2:$B$501=A7)*('Injection Sales'!$A$2:$A$501=_xlfn.MAXIFS('Injection Sales'!$A$2:$A$501,'Injection Sales'!$B$2:$B$501,A7))),'Injection Sales'!$E$2:$E$501),"")) | H7: =IF(OR(A7="",COUNTIF('Injection Sales'!$B$2:$B$501,A7)=0),"",IFERROR(LOOKUP(2,1/(('Injection Sales'!$B$2:$B$501=A7)*('Injection Sales'!$A$2:$A$501=_xlfn.MAXIFS('Injection Sales'!$A$2:$A$501,'Injection Sales'!$B$2:$B$501,A7))),'Injection Sales'!$H$2:$H$501),"")) | I7: =IF(OR(A7="",D7=""),"",IF(TODAY()-D7<=Settings!$B$7,"Active","Inactive"))
C8: =IF(OR(A8="",COUNTIF('Injection Sales'!$B$2:$B$501,A8)+COUNTIF('Protein Sales'!$B$2:$B$501,A8)+COUNTIF('Diet Support'!$B$2:$B$501,A8)=0),"",MIN(IF(COUNTIF('Injection Sales'!$B$2:$B$501,A8),_xlfn.MINIFS('Injection Sales'!$A$2:$A$501,'Injection Sales'!$B$2:$B$501,A8),99999),IF(COUNTIF('Protein Sales'!$B$2:$B$501,A8),_xlfn.MINIFS('Protein Sales'!$A$2:$A$501,'Protein Sales'!$B$2:$B$501,A8),99999),IF(COUNTIF('Diet Support'!$B$2:$B$501,A8),_xlfn.MINIFS('Diet Support'!$A$2:$A$501,'Diet Support'!$B$2:$B$501,A8),99999))) | D8: =IF(OR(A8="",COUNTIF('Injection Sales'!$B$2:$B$501,A8)+COUNTIF('Protein Sales'!$B$2:$B$501,A8)+COUNTIF('Diet Support'!$B$2:$B$501,A8)=0),"",MAX(_xlfn.MAXIFS('Injection Sales'!$A$2:$A$501,'Injection Sales'!$B$2:$B$501,A8),_xlfn.MAXIFS('Protein Sales'!$A$2:$A$501,'Protein Sales'!$B$2:$B$501,A8),_xlfn.MAXIFS('Diet Support'!$A$2:$A$501,'Diet Support'!$B$2:$B$501,A8))) | E8: =IF(A8="","",COUNTIF('Injection Sales'!$B$2:$B$501,A8)+COUNTIF('Protein Sales'!$B$2:$B$501,A8)+COUNTIF('Diet Support'!$B$2:$B$501,A8)) | F8: =IF(A8="","",SUMIF('Injection Sales'!$B$2:$B$501,A8,'Injection Sales'!$G$2:$G$501)+SUMIF('Protein Sales'!$B$2:$B$501,A8,'Protein Sales'!$F$2:$F$501)+SUMIF('Diet Support'!$B$2:$B$501,A8,'Diet Support'!$E$2:$E$501)) | G8: =IF(OR(A8="",COUNTIF('Injection Sales'!$B$2:$B$501,A8)=0),"",IFERROR(LOOKUP(2,1/(('Injection Sales'!$B$2:$B$501=A8)*('Injection Sales'!$A$2:$A$501=_xlfn.MAXIFS('Injection Sales'!$A$2:$A$501,'Injection Sales'!$B$2:$B$501,A8))),'Injection Sales'!$E$2:$E$501),"")) | H8: =IF(OR(A8="",COUNTIF('Injection Sales'!$B$2:$B$501,A8)=0),"",IFERROR(LOOKUP(2,1/(('Injection Sales'!$B$2:$B$501=A8)*('Injection Sales'!$A$2:$A$501=_xlfn.MAXIFS('Injection Sales'!$A$2:$A$501,'Injection Sales'!$B$2:$B$501,A8))),'Injection Sales'!$H$2:$H$501),"")) | I8: =IF(OR(A8="",D8=""),"",IF(TODAY()-D8<=Settings!$B$7,"Active","Inactive"))
C9: =IF(OR(A9="",COUNTIF('Injection Sales'!$B$2:$B$501,A9)+COUNTIF('Protein Sales'!$B$2:$B$501,A9)+COUNTIF('Diet Support'!$B$2:$B$501,A9)=0),"",MIN(IF(COUNTIF('Injection Sales'!$B$2:$B$501,A9),_xlfn.MINIFS('Injection Sales'!$A$2:$A$501,'Injection Sales'!$B$2:$B$501,A9),99999),IF(COUNTIF('Protein Sales'!$B$2:$B$501,A9),_xlfn.MINIFS('Protein Sales'!$A$2:$A$501,'Protein Sales'!$B$2:$B$501,A9),99999),IF(COUNTIF('Diet Support'!$B$2:$B$501,A9),_xlfn.MINIFS('Diet Support'!$A$2:$A$501,'Diet Support'!$B$2:$B$501,A9),99999))) | D9: =IF(OR(A9="",COUNTIF('Injection Sales'!$B$2:$B$501,A9)+COUNTIF('Protein Sales'!$B$2:$B$501,A9)+COUNTIF('Diet Support'!$B$2:$B$501,A9)=0),"",MAX(_xlfn.MAXIFS('Injection Sales'!$A$2:$A$501,'Injection Sales'!$B$2:$B$501,A9),_xlfn.MAXIFS('Protein Sales'!$A$2:$A$501,'Protein Sales'!$B$2:$B$501,A9),_xlfn.MAXIFS('Diet Support'!$A$2:$A$501,'Diet Support'!$B$2:$B$501,A9))) | E9: =IF(A9="","",COUNTIF('Injection Sales'!$B$2:$B$501,A9)+COUNTIF('Protein Sales'!$B$2:$B$501,A9)+COUNTIF('Diet Support'!$B$2:$B$501,A9)) | F9: =IF(A9="","",SUMIF('Injection Sales'!$B$2:$B$501,A9,'Injection Sales'!$G$2:$G$501)+SUMIF('Protein Sales'!$B$2:$B$501,A9,'Protein Sales'!$F$2:$F$501)+SUMIF('Diet Support'!$B$2:$B$501,A9,'Diet Support'!$E$2:$E$501)) | G9: =IF(OR(A9="",COUNTIF('Injection Sales'!$B$2:$B$501,A9)=0),"",IFERROR(LOOKUP(2,1/(('Injection Sales'!$B$2:$B$501=A9)*('Injection Sales'!$A$2:$A$501=_xlfn.MAXIFS('Injection Sales'!$A$2:$A$501,'Injection Sales'!$B$2:$B$501,A9))),'Injection Sales'!$E$2:$E$501),"")) | H9: =IF(OR(A9="",COUNTIF('Injection Sales'!$B$2:$B$501,A9)=0),"",IFERROR(LOOKUP(2,1/(('Injection Sales'!$B$2:$B$501=A9)*('Injection Sales'!$A$2:$A$501=_xlfn.MAXIFS('Injection Sales'!$A$2:$A$501,'Injection Sales'!$B$2:$B$501,A9))),'Injection Sales'!$H$2:$H$501),"")) | I9: =IF(OR(A9="",D9=""),"",IF(TODAY()-D9<=Settings!$B$7,"Active","Inactive"))
C10: =IF(OR(A10="",COUNTIF('Injection Sales'!$B$2:$B$501,A10)+COUNTIF('Protein Sales'!$B$2:$B$501,A10)+COUNTIF('Diet Support'!$B$2:$B$501,A10)=0),"",MIN(IF(COUNTIF('Injection Sales'!$B$2:$B$501,A10),_xlfn.MINIFS('Injection Sales'!$A$2:$A$501,'Injection Sales'!$B$2:$B$501,A10),99999),IF(COUNTIF('Protein Sales'!$B$2:$B$501,A10),_xlfn.MINIFS('Protein Sales'!$A$2:$A$501,'Protein Sales'!$B$2:$B$501,A10),99999),IF(COUNTIF('Diet Support'!$B$2:$B$501,A10),_xlfn.MINIFS('Diet Support'!$A$2:$A$501,'Diet Support'!$B$2:$B$501,A10),99999))) | D10: =IF(OR(A10="",COUNTIF('Injection Sales'!$B$2:$B$501,A10)+COUNTIF('Protein Sales'!$B$2:$B$501,A10)+COUNTIF('Diet Support'!$B$2:$B$501,A10)=0),"",MAX(_xlfn.MAXIFS('Injection Sales'!$A$2:$A$501,'Injection Sales'!$B$2:$B$501,A10),_xlfn.MAXIFS('Protein Sales'!$A$2:$A$501,'Protein Sales'!$B$2:$B$501,A10),_xlfn.MAXIFS('Diet Support'!$A$2:$A$501,'Diet Support'!$B$2:$B$501,A10))) | E10: =IF(A10="","",COUNTIF('Injection Sales'!$B$2:$B$501,A10)+COUNTIF('Protein Sales'!$B$2:$B$501,A10)+COUNTIF('Diet Support'!$B$2:$B$501,A10)) | F10: =IF(A10="","",SUMIF('Injection Sales'!$B$2:$B$501,A10,'Injection Sales'!$G$2:$G$501)+SUMIF('Protein Sales'!$B$2:$B$501,A10,'Protein Sales'!$F$2:$F$501)+SUMIF('Diet Support'!$B$2:$B$501,A10,'Diet Support'!$E$2:$E$501)) | G10: =IF(OR(A10="",COUNTIF('Injection Sales'!$B$2:$B$501,A10)=0),"",IFERROR(LOOKUP(2,1/(('Injection Sales'!$B$2:$B$501=A10)*('Injection Sales'!$A$2:$A$501=_xlfn.MAXIFS('Injection Sales'!$A$2:$A$501,'Injection Sales'!$B$2:$B$501,A10))),'Injection Sales'!$E$2:$E$501),"")) | H10: =IF(OR(A10="",COUNTIF('Injection Sales'!$B$2:$B$501,A10)=0),"",IFERROR(LOOKUP(2,1/(('Injection Sales'!$B$2:$B$501=A10)*('Injection Sales'!$A$2:$A$501=_xlfn.MAXIFS('Injection Sales'!$A$2:$A$501,'Injection Sales'!$B$2:$B$501,A10))),'Injection Sales'!$H$2:$H$501),"")) | I10: =IF(OR(A10="",D10=""),"",IF(TODAY()-D10<=Settings!$B$7,"Active","Inactive"))
C11: =IF(OR(A11="",COUNTIF('Injection Sales'!$B$2:$B$501,A11)+COUNTIF('Protein Sales'!$B$2:$B$501,A11)+COUNTIF('Diet Support'!$B$2:$B$501,A11)=0),"",MIN(IF(COUNTIF('Injection Sales'!$B$2:$B$501,A11),_xlfn.MINIFS('Injection Sales'!$A$2:$A$501,'Injection Sales'!$B$2:$B$501,A11),99999),IF(COUNTIF('Protein Sales'!$B$2:$B$501,A11),_xlfn.MINIFS('Protein Sales'!$A$2:$A$501,'Protein Sales'!$B$2:$B$501,A11),99999),IF(COUNTIF('Diet Support'!$B$2:$B$501,A11),_xlfn.MINIFS('Diet Support'!$A$2:$A$501,'Diet Support'!$B$2:$B$501,A11),99999))) | D11: =IF(OR(A11="",COUNTIF('Injection Sales'!$B$2:$B$501,A11)+COUNTIF('Protein Sales'!$B$2:$B$501,A11)+COUNTIF('Diet Support'!$B$2:$B$501,A11)=0),"",MAX(_xlfn.MAXIFS('Injection Sales'!$A$2:$A$501,'Injection Sales'!$B$2:$B$501,A11),_xlfn.MAXIFS('Protein Sales'!$A$2:$A$501,'Protein Sales'!$B$2:$B$501,A11),_xlfn.MAXIFS('Diet Support'!$A$2:$A$501,'Diet Support'!$B$2:$B$501,A11))) | E11: =IF(A11="","",COUNTIF('Injection Sales'!$B$2:$B$501,A11)+COUNTIF('Protein Sales'!$B$2:$B$501,A11)+COUNTIF('Diet Support'!$B$2:$B$501,A11)) | F11: =IF(A11="","",SUMIF('Injection Sales'!$B$2:$B$501,A11,'Injection Sales'!$G$2:$G$501)+SUMIF('Protein Sales'!$B$2:$B$501,A11,'Protein Sales'!$F$2:$F$501)+SUMIF('Diet Support'!$B$2:$B$501,A11,'Diet Support'!$E$2:$E$501)) | G11: =IF(OR(A11="",COUNTIF('Injection Sales'!$B$2:$B$501,A11)=0),"",IFERROR(LOOKUP(2,1/(('Injection Sales'!$B$2:$B$501=A11)*('Injection Sales'!$A$2:$A$501=_xlfn.MAXIFS('Injection Sales'!$A$2:$A$501,'Injection Sales'!$B$2:$B$501,A11))),'Injection Sales'!$E$2:$E$501),"")) | H11: =IF(OR(A11="",COUNTIF('Injection Sales'!$B$2:$B$501,A11)=0),"",IFERROR(LOOKUP(2,1/(('Injection Sales'!$B$2:$B$501=A11)*('Injection Sales'!$A$2:$A$501=_xlfn.MAXIFS('Injection Sales'!$A$2:$A$501,'Injection Sales'!$B$2:$B$501,A11))),'Injection Sales'!$H$2:$H$501),"")) | I11: =IF(OR(A11="",D11=""),"",IF(TODAY()-D11<=Settings!$B$7,"Active","Inactive"))
C12: =IF(OR(A12="",COUNTIF('Injection Sales'!$B$2:$B$501,A12)+COUNTIF('Protein Sales'!$B$2:$B$501,A12)+COUNTIF('Diet Support'!$B$2:$B$501,A12)=0),"",MIN(IF(COUNTIF('Injection Sales'!$B$2:$B$501,A12),_xlfn.MINIFS('Injection Sales'!$A$2:$A$501,'Injection Sales'!$B$2:$B$501,A12),99999),IF(COUNTIF('Protein Sales'!$B$2:$B$501,A12),_xlfn.MINIFS('Protein Sales'!$A$2:$A$501,'Protein Sales'!$B$2:$B$501,A12),99999),IF(COUNTIF('Diet Support'!$B$2:$B$501,A12),_xlfn.MINIFS('Diet Support'!$A$2:$A$501,'Diet Support'!$B$2:$B$501,A12),99999))) | D12: =IF(OR(A12="",COUNTIF('Injection Sales'!$B$2:$B$501,A12)+COUNTIF('Protein Sales'!$B$2:$B$501,A12)+COUNTIF('Diet Support'!$B$2:$B$501,A12)=0),"",MAX(_xlfn.MAXIFS('Injection Sales'!$A$2:$A$501,'Injection Sales'!$B$2:$B$501,A12),_xlfn.MAXIFS('Protein Sales'!$A$2:$A$501,'Protein Sales'!$B$2:$B$501,A12),_xlfn.MAXIFS('Diet Support'!$A$2:$A$501,'Diet Support'!$B$2:$B$501,A12))) | E12: =IF(A12="","",COUNTIF('Injection Sales'!$B$2:$B$501,A12)+COUNTIF('Protein Sales'!$B$2:$B$501,A12)+COUNTIF('Diet Support'!$B$2:$B$501,A12)) | F12: =IF(A12="","",SUMIF('Injection Sales'!$B$2:$B$501,A12,'Injection Sales'!$G$2:$G$501)+SUMIF('Protein Sales'!$B$2:$B$501,A12,'Protein Sales'!$F$2:$F$501)+SUMIF('Diet Support'!$B$2:$B$501,A12,'Diet Support'!$E$2:$E$501)) | G12: =IF(OR(A12="",COUNTIF('Injection Sales'!$B$2:$B$501,A12)=0),"",IFERROR(LOOKUP(2,1/(('Injection Sales'!$B$2:$B$501=A12)*('Injection Sales'!$A$2:$A$501=_xlfn.MAXIFS('Injection Sales'!$A$2:$A$501,'Injection Sales'!$B$2:$B$501,A12))),'Injection Sales'!$E$2:$E$501),"")) | H12: =IF(OR(A12="",COUNTIF('Injection Sales'!$B$2:$B$501,A12)=0),"",IFERROR(LOOKUP(2,1/(('Injection Sales'!$B$2:$B$501=A12)*('Injection Sales'!$A$2:$A$501=_xlfn.MAXIFS('Injection Sales'!$A$2:$A$501,'Injection Sales'!$B$2:$B$501,A12))),'Injection Sales'!$H$2:$H$501),"")) | I12: =IF(OR(A12="",D12=""),"",IF(TODAY()-D12<=Settings!$B$7,"Active","Inactive"))
C13: =IF(OR(A13="",COUNTIF('Injection Sales'!$B$2:$B$501,A13)+COUNTIF('Protein Sales'!$B$2:$B$501,A13)+COUNTIF('Diet Support'!$B$2:$B$501,A13)=0),"",MIN(IF(COUNTIF('Injection Sales'!$B$2:$B$501,A13),_xlfn.MINIFS('Injection Sales'!$A$2:$A$501,'Injection Sales'!$B$2:$B$501,A13),99999),IF(COUNTIF('Protein Sales'!$B$2:$B$501,A13),_xlfn.MINIFS('Protein Sales'!$A$2:$A$501,'Protein Sales'!$B$2:$B$501,A13),99999),IF(COUNTIF('Diet Support'!$B$2:$B$501,A13),_xlfn.MINIFS('Diet Support'!$A$2:$A$501,'Diet Support'!$B$2:$B$501,A13),99999))) | D13: =IF(OR(A13="",COUNTIF('Injection Sales'!$B$2:$B$501,A13)+COUNTIF('Protein Sales'!$B$2:$B$501,A13)+COUNTIF('Diet Support'!$B$2:$B$501,A13)=0),"",MAX(_xlfn.MAXIFS('Injection Sales'!$A$2:$A$501,'Injection Sales'!$B$2:$B$501,A13),_xlfn.MAXIFS('Protein Sales'!$A$2:$A$501,'Protein Sales'!$B$2:$B$501,A13),_xlfn.MAXIFS('Diet Support'!$A$2:$A$501,'Diet Support'!$B$2:$B$501,A13))) | E13: =IF(A13="","",COUNTIF('Injection Sales'!$B$2:$B$501,A13)+COUNTIF('Protein Sales'!$B$2:$B$501,A13)+COUNTIF('Diet Support'!$B$2:$B$501,A13)) | F13: =IF(A13="","",SUMIF('Injection Sales'!$B$2:$B$501,A13,'Injection Sales'!$G$2:$G$501)+SUMIF('Protein Sales'!$B$2:$B$501,A13,'Protein Sales'!$F$2:$F$501)+SUMIF('Diet Support'!$B$2:$B$501,A13,'Diet Support'!$E$2:$E$501)) | G13: =IF(OR(A13="",COUNTIF('Injection Sales'!$B$2:$B$501,A13)=0),"",IFERROR(LOOKUP(2,1/(('Injection Sales'!$B$2:$B$501=A13)*('Injection Sales'!$A$2:$A$501=_xlfn.MAXIFS('Injection Sales'!$A$2:$A$501,'Injection Sales'!$B$2:$B$501,A13))),'Injection Sales'!$E$2:$E$501),"")) | H13: =IF(OR(A13="",COUNTIF('Injection Sales'!$B$2:$B$501,A13)=0),"",IFERROR(LOOKUP(2,1/(('Injection Sales'!$B$2:$B$501=A13)*('Injection Sales'!$A$2:$A$501=_xlfn.MAXIFS('Injection Sales'!$A$2:$A$501,'Injection Sales'!$B$2:$B$501,A13))),'Injection Sales'!$H$2:$H$501),"")) | I13: =IF(OR(A13="",D13=""),"",IF(TODAY()-D13<=Settings!$B$7,"Active","Inactive"))
C14: =IF(OR(A14="",COUNTIF('Injection Sales'!$B$2:$B$501,A14)+COUNTIF('Protein Sales'!$B$2:$B$501,A14)+COUNTIF('Diet Support'!$B$2:$B$501,A14)=0),"",MIN(IF(COUNTIF('Injection Sales'!$B$2:$B$501,A14),_xlfn.MINIFS('Injection Sales'!$A$2:$A$501,'Injection Sales'!$B$2:$B$501,A14),99999),IF(COUNTIF('Protein Sales'!$B$2:$B$501,A14),_xlfn.MINIFS('Protein Sales'!$A$2:$A$501,'Protein Sales'!$B$2:$B$501,A14),99999),IF(COUNTIF('Diet Support'!$B$2:$B$501,A14),_xlfn.MINIFS('Diet Support'!$A$2:$A$501,'Diet Support'!$B$2:$B$501,A14),99999))) | D14: =IF(OR(A14="",COUNTIF('Injection Sales'!$B$2:$B$501,A14)+COUNTIF('Protein Sales'!$B$2:$B$501,A14)+COUNTIF('Diet Support'!$B$2:$B$501,A14)=0),"",MAX(_xlfn.MAXIFS('Injection Sales'!$A$2:$A$501,'Injection Sales'!$B$2:$B$501,A14),_xlfn.MAXIFS('Protein Sales'!$A$2:$A$501,'Protein Sales'!$B$2:$B$501,A14),_xlfn.MAXIFS('Diet Support'!$A$2:$A$501,'Diet Support'!$B$2:$B$501,A14))) | E14: =IF(A14="","",COUNTIF('Injection Sales'!$B$2:$B$501,A14)+COUNTIF('Protein Sales'!$B$2:$B$501,A14)+COUNTIF('Diet Support'!$B$2:$B$501,A14)) | F14: =IF(A14="","",SUMIF('Injection Sales'!$B$2:$B$501,A14,'Injection Sales'!$G$2:$G$501)+SUMIF('Protein Sales'!$B$2:$B$501,A14,'Protein Sales'!$F$2:$F$501)+SUMIF('Diet Support'!$B$2:$B$501,A14,'Diet Support'!$E$2:$E$501)) | G14: =IF(OR(A14="",COUNTIF('Injection Sales'!$B$2:$B$501,A14)=0),"",IFERROR(LOOKUP(2,1/(('Injection Sales'!$B$2:$B$501=A14)*('Injection Sales'!$A$2:$A$501=_xlfn.MAXIFS('Injection Sales'!$A$2:$A$501,'Injection Sales'!$B$2:$B$501,A14))),'Injection Sales'!$E$2:$E$501),"")) | H14: =IF(OR(A14="",COUNTIF('Injection Sales'!$B$2:$B$501,A14)=0),"",IFERROR(LOOKUP(2,1/(('Injection Sales'!$B$2:$B$501=A14)*('Injection Sales'!$A$2:$A$501=_xlfn.MAXIFS('Injection Sales'!$A$2:$A$501,'Injection Sales'!$B$2:$B$501,A14))),'Injection Sales'!$H$2:$H$501),"")) | I14: =IF(OR(A14="",D14=""),"",IF(TODAY()-D14<=Settings!$B$7,"Active","Inactive"))
... C501: =IF(OR(A501="",COUNTIF('Injection Sales'!$B$2:$B$501,A501)+COUNTIF('Protein Sales'!$B$2:$B$501,A501)+COUNTIF('Diet Support'!$B$2:$B$501,A501)=0),"",MIN(IF(COUNTIF('Injection Sales'!$B$2:$B$501,A501),_xlfn.MINIFS('Injection Sales'!$A$2:$A$501,'Injection Sales'!$B$2:$B$501,A501),99999),IF(COUNTIF('Protein Sales'!$B$2:$B$501,A501),_xlfn.MINIFS('Protein Sales'!$A$2:$A$501,'Protein Sales'!$B$2:$B$501,A501),99999),IF(COUNTIF('Diet Support'!$B$2:$B$501,A501),_xlfn.MINIFS('Diet Support'!$A$2:$A$501,'Diet Support'!$B$2:$B$501,A501),99999))) | D501: =IF(OR(A501="",COUNTIF('Injection Sales'!$B$2:$B$501,A501)+COUNTIF('Protein Sales'!$B$2:$B$501,A501)+COUNTIF('Diet Support'!$B$2:$B$501,A501)=0),"",MAX(_xlfn.MAXIFS('Injection Sales'!$A$2:$A$501,'Injection Sales'!$B$2:$B$501,A501),_xlfn.MAXIFS('Protein Sales'!$A$2:$A$501,'Protein Sales'!$B$2:$B$501,A501),_xlfn.MAXIFS('Diet Support'!$A$2:$A$501,'Diet Support'!$B$2:$B$501,A501))) | E501: =IF(A501="","",COUNTIF('Injection Sales'!$B$2:$B$501,A501)+COUNTIF('Protein Sales'!$B$2:$B$501,A501)+COUNTIF('Diet Support'!$B$2:$B$501,A501)) | F501: =IF(A501="","",SUMIF('Injection Sales'!$B$2:$B$501,A501,'Injection Sales'!$G$2:$G$501)+SUMIF('Protein Sales'!$B$2:$B$501,A501,'Protein Sales'!$F$2:$F$501)+SUMIF('Diet Support'!$B$2:$B$501,A501,'Diet Support'!$E$2:$E$501)) | G501: =IF(OR(A501="",COUNTIF('Injection Sales'!$B$2:$B$501,A501)=0),"",IFERROR(LOOKUP(2,1/(('Injection Sales'!$B$2:$B$501=A501)*('Injection Sales'!$A$2:$A$501=_xlfn.MAXIFS('Injection Sales'!$A$2:$A$501,'Injection Sales'!$B$2:$B$501,A501))),'Injection Sales'!$E$2:$E$501),"")) | H501: =IF(OR(A501="",COUNTIF('Injection Sales'!$B$2:$B$501,A501)=0),"",IFERROR(LOOKUP(2,1/(('Injection Sales'!$B$2:$B$501=A501)*('Injection Sales'!$A$2:$A$501=_xlfn.MAXIFS('Injection Sales'!$A$2:$A$501,'Injection Sales'!$B$2:$B$501,A501))),'Injection Sales'!$H$2:$H$501),"")) | I501: =IF(OR(A501="",D501=""),"",IF(TODAY()-D501<=Settings!$B$7,"Active","Inactive"))

Sheet Injection Sales
A1: Purchase Date | B1: Patient Name | C1: Mobile Number | D1: New / Renewal | E1: Product | F1: Qty (pens) | G1: Sale Amount (₹) | H1: Reference Team | I1: Shared Reference | J1: Shared % | K1: Assigned Dietitian | L1: Total Incentive (₹) | M1: Reference Incentive (₹) | N1: Shared Incentive (₹) | O1: Notes
A2: 46266 | B2: Asha Sharma | C2: =IF(B2="","",IFERROR(INDEX(Patients!$B$2:$B$501,MATCH(B2,Patients!$A$2:$A$501,0))&"","")) -> 9876543210 | D2: New | E2: Mounjaro 5mg | F2: 1 | G2: 5000 | H2: Murshida | L2: =IF(E2="","",IFERROR(INDEX(Settings!$D$13:$D$32,MATCH(E2,Settings!$A$13:$A$32,0)),0)*IF(F2="",1,F2)) -> 1000 | M2: =IF(L2="","",IF(I2="",L2,L2*(1-IF(J2="",Settings!$B$6,J2)))) -> 1000 | N2: =IF(OR(L2="",I2=""),"",L2-M2) | O2: EXAMPLE row – overwrite or delete
C3: =IF(B3="","",IFERROR(INDEX(Patients!$B$2:$B$501,MATCH(B3,Patients!$A$2:$A$501,0))&"","")) | L3: =IF(E3="","",IFERROR(INDEX(Settings!$D$13:$D$32,MATCH(E3,Settings!$A$13:$A$32,0)),0)*IF(F3="",1,F3)) | M3: =IF(L3="","",IF(I3="",L3,L3*(1-IF(J3="",Settings!$B$6,J3)))) | N3: =IF(OR(L3="",I3=""),"",L3-M3)
C4: =IF(B4="","",IFERROR(INDEX(Patients!$B$2:$B$501,MATCH(B4,Patients!$A$2:$A$501,0))&"","")) | L4: =IF(E4="","",IFERROR(INDEX(Settings!$D$13:$D$32,MATCH(E4,Settings!$A$13:$A$32,0)),0)*IF(F4="",1,F4)) | M4: =IF(L4="","",IF(I4="",L4,L4*(1-IF(J4="",Settings!$B$6,J4)))) | N4: =IF(OR(L4="",I4=""),"",L4-M4)
C5: =IF(B5="","",IFERROR(INDEX(Patients!$B$2:$B$501,MATCH(B5,Patients!$A$2:$A$501,0))&"","")) | L5: =IF(E5="","",IFERROR(INDEX(Settings!$D$13:$D$32,MATCH(E5,Settings!$A$13:$A$32,0)),0)*IF(F5="",1,F5)) | M5: =IF(L5="","",IF(I5="",L5,L5*(1-IF(J5="",Settings!$B$6,J5)))) | N5: =IF(OR(L5="",I5=""),"",L5-M5)
C6: =IF(B6="","",IFERROR(INDEX(Patients!$B$2:$B$501,MATCH(B6,Patients!$A$2:$A$501,0))&"","")) | L6: =IF(E6="","",IFERROR(INDEX(Settings!$D$13:$D$32,MATCH(E6,Settings!$A$13:$A$32,0)),0)*IF(F6="",1,F6)) | M6: =IF(L6="","",IF(I6="",L6,L6*(1-IF(J6="",Settings!$B$6,J6)))) | N6: =IF(OR(L6="",I6=""),"",L6-M6)
C7: =IF(B7="","",IFERROR(INDEX(Patients!$B$2:$B$501,MATCH(B7,Patients!$A$2:$A$501,0))&"","")) | L7: =IF(E7="","",IFERROR(INDEX(Settings!$D$13:$D$32,MATCH(E7,Settings!$A$13:$A$32,0)),0)*IF(F7="",1,F7)) | M7: =IF(L7="","",IF(I7="",L7,L7*(1-IF(J7="",Settings!$B$6,J7)))) | N7: =IF(OR(L7="",I7=""),"",L7-M7)
C8: =IF(B8="","",IFERROR(INDEX(Patients!$B$2:$B$501,MATCH(B8,Patients!$A$2:$A$501,0))&"","")) | L8: =IF(E8="","",IFERROR(INDEX(Settings!$D$13:$D$32,MATCH(E8,Settings!$A$13:$A$32,0)),0)*IF(F8="",1,F8)) | M8: =IF(L8="","",IF(I8="",L8,L8*(1-IF(J8="",Settings!$B$6,J8)))) | N8: =IF(OR(L8="",I8=""),"",L8-M8)
C9: =IF(B9="","",IFERROR(INDEX(Patients!$B$2:$B$501,MATCH(B9,Patients!$A$2:$A$501,0))&"","")) | L9: =IF(E9="","",IFERROR(INDEX(Settings!$D$13:$D$32,MATCH(E9,Settings!$A$13:$A$32,0)),0)*IF(F9="",1,F9)) | M9: =IF(L9="","",IF(I9="",L9,L9*(1-IF(J9="",Settings!$B$6,J9)))) | N9: =IF(OR(L9="",I9=""),"",L9-M9)
C10: =IF(B10="","",IFERROR(INDEX(Patients!$B$2:$B$501,MATCH(B10,Patients!$A$2:$A$501,0))&"","")) | L10: =IF(E10="","",IFERROR(INDEX(Settings!$D$13:$D$32,MATCH(E10,Settings!$A$13:$A$32,0)),0)*IF(F10="",1,F10)) | M10: =IF(L10="","",IF(I10="",L10,L10*(1-IF(J10="",Settings!$B$6,J10)))) | N10: =IF(OR(L10="",I10=""),"",L10-M10)
C11: =IF(B11="","",IFERROR(INDEX(Patients!$B$2:$B$501,MATCH(B11,Patients!$A$2:$A$501,0))&"","")) | L11: =IF(E11="","",IFERROR(INDEX(Settings!$D$13:$D$32,MATCH(E11,Settings!$A$13:$A$32,0)),0)*IF(F11="",1,F11)) | M11: =IF(L11="","",IF(I11="",L11,L11*(1-IF(J11="",Settings!$B$6,J11)))) | N11: =IF(OR(L11="",I11=""),"",L11-M11)
C12: =IF(B12="","",IFERROR(INDEX(Patients!$B$2:$B$501,MATCH(B12,Patients!$A$2:$A$501,0))&"","")) | L12: =IF(E12="","",IFERROR(INDEX(Settings!$D$13:$D$32,MATCH(E12,Settings!$A$13:$A$32,0)),0)*IF(F12="",1,F12)) | M12: =IF(L12="","",IF(I12="",L12,L12*(1-IF(J12="",Settings!$B$6,J12)))) | N12: =IF(OR(L12="",I12=""),"",L12-M12)
C13: =IF(B13="","",IFERROR(INDEX(Patients!$B$2:$B$501,MATCH(B13,Patients!$A$2:$A$501,0))&"","")) | L13: =IF(E13="","",IFERROR(INDEX(Settings!$D$13:$D$32,MATCH(E13,Settings!$A$13:$A$32,0)),0)*IF(F13="",1,F13)) | M13: =IF(L13="","",IF(I13="",L13,L13*(1-IF(J13="",Settings!$B$6,J13)))) | N13: =IF(OR(L13="",I13=""),"",L13-M13)
C14: =IF(B14="","",IFERROR(INDEX(Patients!$B$2:$B$501,MATCH(B14,Patients!$A$2:$A$501,0))&"","")) | L14: =IF(E14="","",IFERROR(INDEX(Settings!$D$13:$D$32,MATCH(E14,Settings!$A$13:$A$32,0)),0)*IF(F14="",1,F14)) | M14: =IF(L14="","",IF(I14="",L14,L14*(1-IF(J14="",Settings!$B$6,J14)))) | N14: =IF(OR(L14="",I14=""),"",L14-M14)
... C501: =IF(B501="","",IFERROR(INDEX(Patients!$B$2:$B$501,MATCH(B501,Patients!$A$2:$A$501,0))&"","")) | L501: =IF(E501="","",IFERROR(INDEX(Settings!$D$13:$D$32,MATCH(E501,Settings!$A$13:$A$32,0)),0)*IF(F501="",1,F501)) | M501: =IF(L501="","",IF(I501="",L501,L501*(1-IF(J501="",Settings!$B$6,J501)))) | N501: =IF(OR(L501="",I501=""),"",L501-M501)

Sheet Protein Sales
A1: Date | B1: Patient Name | C1: Mobile Number | D1: Protein Type | E1: Quantity | F1: Sale Amount (₹) | G1: Reference | H1: Shared Reference | I1: Shared % | J1: Total Incentive (₹) | K1: Reference Incentive (₹) | L1: Shared Incentive (₹) | M1: Notes
A2: 46267 | B2: Asha Sharma | C2: =IF(B2="","",IFERROR(INDEX(Patients!$B$2:$B$501,MATCH(B2,Patients!$A$2:$A$501,0))&"","")) -> 9876543210 | D2: Protein Sachets | E2: 30 | F2: 3000 | G2: Murshida | J2: =IF(D2="","",IFERROR(INDEX(Settings!$D$36:$D$45,MATCH(D2,Settings!$A$36:$A$45,0)),0)) -> 500 | K2: =IF(J2="","",IF(H2="",J2,J2*(1-IF(I2="",Settings!$B$6,I2)))) -> 500 | L2: =IF(OR(J2="",H2=""),"",J2-K2) | M2: EXAMPLE row – overwrite or delete
C3: =IF(B3="","",IFERROR(INDEX(Patients!$B$2:$B$501,MATCH(B3,Patients!$A$2:$A$501,0))&"","")) | J3: =IF(D3="","",IFERROR(INDEX(Settings!$D$36:$D$45,MATCH(D3,Settings!$A$36:$A$45,0)),0)) | K3: =IF(J3="","",IF(H3="",J3,J3*(1-IF(I3="",Settings!$B$6,I3)))) | L3: =IF(OR(J3="",H3=""),"",J3-K3)
C4: =IF(B4="","",IFERROR(INDEX(Patients!$B$2:$B$501,MATCH(B4,Patients!$A$2:$A$501,0))&"","")) | J4: =IF(D4="","",IFERROR(INDEX(Settings!$D$36:$D$45,MATCH(D4,Settings!$A$36:$A$45,0)),0)) | K4: =IF(J4="","",IF(H4="",J4,J4*(1-IF(I4="",Settings!$B$6,I4)))) | L4: =IF(OR(J4="",H4=""),"",J4-K4)
C5: =IF(B5="","",IFERROR(INDEX(Patients!$B$2:$B$501,MATCH(B5,Patients!$A$2:$A$501,0))&"","")) | J5: =IF(D5="","",IFERROR(INDEX(Settings!$D$36:$D$45,MATCH(D5,Settings!$A$36:$A$45,0)),0)) | K5: =IF(J5="","",IF(H5="",J5,J5*(1-IF(I5="",Settings!$B$6,I5)))) | L5: =IF(OR(J5="",H5=""),"",J5-K5)
C6: =IF(B6="","",IFERROR(INDEX(Patients!$B$2:$B$501,MATCH(B6,Patients!$A$2:$A$501,0))&"","")) | J6: =IF(D6="","",IFERROR(INDEX(Settings!$D$36:$D$45,MATCH(D6,Settings!$A$36:$A$45,0)),0)) | K6: =IF(J6="","",IF(H6="",J6,J6*(1-IF(I6="",Settings!$B$6,I6)))) | L6: =IF(OR(J6="",H6=""),"",J6-K6)
C7: =IF(B7="","",IFERROR(INDEX(Patients!$B$2:$B$501,MATCH(B7,Patients!$A$2:$A$501,0))&"","")) | J7: =IF(D7="","",IFERROR(INDEX(Settings!$D$36:$D$45,MATCH(D7,Settings!$A$36:$A$45,0)),0)) | K7: =IF(J7="","",IF(H7="",J7,J7*(1-IF(I7="",Settings!$B$6,I7)))) | L7: =IF(OR(J7="",H7=""),"",J7-K7)
C8: =IF(B8="","",IFERROR(INDEX(Patients!$B$2:$B$501,MATCH(B8,Patients!$A$2:$A$501,0))&"","")) | J8: =IF(D8="","",IFERROR(INDEX(Settings!$D$36:$D$45,MATCH(D8,Settings!$A$36:$A$45,0)),0)) | K8: =IF(J8="","",IF(H8="",J8,J8*(1-IF(I8="",Settings!$B$6,I8)))) | L8: =IF(OR(J8="",H8=""),"",J8-K8)
C9: =IF(B9="","",IFERROR(INDEX(Patients!$B$2:$B$501,MATCH(B9,Patients!$A$2:$A$501,0))&"","")) | J9: =IF(D9="","",IFERROR(INDEX(Settings!$D$36:$D$45,MATCH(D9,Settings!$A$36:$A$45,0)),0)) | K9: =IF(J9="","",IF(H9="",J9,J9*(1-IF(I9="",Settings!$B$6,I9)))) | L9: =IF(OR(J9="",H9=""),"",J9-K9)
C10: =IF(B10="","",IFERROR(INDEX(Patients!$B$2:$B$501,MATCH(B10,Patients!$A$2:$A$501,0))&"","")) | J10: =IF(D10="","",IFERROR(INDEX(Settings!$D$36:$D$45,MATCH(D10,Settings!$A$36:$A$45,0)),0)) | K10: =IF(J10="","",IF(H10="",J10,J10*(1-IF(I10="",Settings!$B$6,I10)))) | L10: =IF(OR(J10="",H10=""),"",J10-K10)
C11: =IF(B11="","",IFERROR(INDEX(Patients!$B$2:$B$501,MATCH(B11,Patients!$A$2:$A$501,0))&"","")) | J11: =IF(D11="","",IFERROR(INDEX(Settings!$D$36:$D$45,MATCH(D11,Settings!$A$36:$A$45,0)),0)) | K11: =IF(J11="","",IF(H11="",J11,J11*(1-IF(I11="",Settings!$B$6,I11)))) | L11: =IF(OR(J11="",H11=""),"",J11-K11)
C12: =IF(B12="","",IFERROR(INDEX(Patients!$B$2:$B$501,MATCH(B12,Patients!$A$2:$A$501,0))&"","")) | J12: =IF(D12="","",IFERROR(INDEX(Settings!$D$36:$D$45,MATCH(D12,Settings!$A$36:$A$45,0)),0)) | K12: =IF(J12="","",IF(H12="",J12,J12*(1-IF(I12="",Settings!$B$6,I12)))) | L12: =IF(OR(J12="",H12=""),"",J12-K12)
C13: =IF(B13="","",IFERROR(INDEX(Patients!$B$2:$B$501,MATCH(B13,Patients!$A$2:$A$501,0))&"","")) | J13: =IF(D13="","",IFERROR(INDEX(Settings!$D$36:$D$45,MATCH(D13,Settings!$A$36:$A$45,0)),0)) | K13: =IF(J13="","",IF(H13="",J13,J13*(1-IF(I13="",Settings!$B$6,I13)))) | L13: =IF(OR(J13="",H13=""),"",J13-K13)
C14: =IF(B14="","",IFERROR(INDEX(Patients!$B$2:$B$501,MATCH(B14,Patients!$A$2:$A$501,0))&"","")) | J14: =IF(D14="","",IFERROR(INDEX(Settings!$D$36:$D$45,MATCH(D14,Settings!$A$36:$A$45,0)),0)) | K14: =IF(J14="","",IF(H14="",J14,J14*(1-IF(I14="",Settings!$B$6,I14)))) | L14: =IF(OR(J14="",H14=""),"",J14-K14)
... C501: =IF(B501="","",IFERROR(INDEX(Patients!$B$2:$B$501,MATCH(B501,Patients!$A$2:$A$501,0))&"","")) | J501: =IF(D501="","",IFERROR(INDEX(Settings!$D$36:$D$45,MATCH(D501,Settings!$A$36:$A$45,0)),0)) | K501: =IF(J501="","",IF(H501="",J501,J501*(1-IF(I501="",Settings!$B$6,I501)))) | L501: =IF(OR(J501="",H501=""),"",J501-K501)

Sheet Diet Support
A1: Date | B1: Patient Name | C1: Mobile Number | D1: Plan | E1: Sale Amount (₹) | F1: Reference | G1: Shared Reference | H1: Shared % | I1: Assigned Dietitian | J1: Total Incentive (₹) | K1: Reference Incentive (₹) | L1: Shared Incentive (₹) | M1: Notes
A2: 46268 | B2: Asha Sharma | C2: =IF(B2="","",IFERROR(INDEX(Patients!$B$2:$B$501,MATCH(B2,Patients!$A$2:$A$501,0))&"","")) -> 9876543210 | D2: 3 Month | E2: 6000 | F2: Murshida | J2: =IF(D2="","",IFERROR(INDEX(Settings!$C$49:$C$54,MATCH(D2,Settings!$A$49:$A$54,0)),0)) -> 2000 | K2: =IF(J2="","",IF(G2="",J2,J2*(1-IF(H2="",Settings!$B$6,H2)))) -> 2000 | L2: =IF(OR(J2="",G2=""),"",J2-K2) | M2: EXAMPLE row – overwrite or delete
C3: =IF(B3="","",IFERROR(INDEX(Patients!$B$2:$B$501,MATCH(B3,Patients!$A$2:$A$501,0))&"","")) | J3: =IF(D3="","",IFERROR(INDEX(Settings!$C$49:$C$54,MATCH(D3,Settings!$A$49:$A$54,0)),0)) | K3: =IF(J3="","",IF(G3="",J3,J3*(1-IF(H3="",Settings!$B$6,H3)))) | L3: =IF(OR(J3="",G3=""),"",J3-K3)
C4: =IF(B4="","",IFERROR(INDEX(Patients!$B$2:$B$501,MATCH(B4,Patients!$A$2:$A$501,0))&"","")) | J4: =IF(D4="","",IFERROR(INDEX(Settings!$C$49:$C$54,MATCH(D4,Settings!$A$49:$A$54,0)),0)) | K4: =IF(J4="","",IF(G4="",J4,J4*(1-IF(H4="",Settings!$B$6,H4)))) | L4: =IF(OR(J4="",G4=""),"",J4-K4)
C5: =IF(B5="","",IFERROR(INDEX(Patients!$B$2:$B$501,MATCH(B5,Patients!$A$2:$A$501,0))&"","")) | J5: =IF(D5="","",IFERROR(INDEX(Settings!$C$49:$C$54,MATCH(D5,Settings!$A$49:$A$54,0)),0)) | K5: =IF(J5="","",IF(G5="",J5,J5*(1-IF(H5="",Settings!$B$6,H5)))) | L5: =IF(OR(J5="",G5=""),"",J5-K5)
C6: =IF(B6="","",IFERROR(INDEX(Patients!$B$2:$B$501,MATCH(B6,Patients!$A$2:$A$501,0))&"","")) | J6: =IF(D6="","",IFERROR(INDEX(Settings!$C$49:$C$54,MATCH(D6,Settings!$A$49:$A$54,0)),0)) | K6: =IF(J6="","",IF(G6="",J6,J6*(1-IF(H6="",Settings!$B$6,H6)))) | L6: =IF(OR(J6="",G6=""),"",J6-K6)
C7: =IF(B7="","",IFERROR(INDEX(Patients!$B$2:$B$501,MATCH(B7,Patients!$A$2:$A$501,0))&"","")) | J7: =IF(D7="","",IFERROR(INDEX(Settings!$C$49:$C$54,MATCH(D7,Settings!$A$49:$A$54,0)),0)) | K7: =IF(J7="","",IF(G7="",J7,J7*(1-IF(H7="",Settings!$B$6,H7)))) | L7: =IF(OR(J7="",G7=""),"",J7-K7)
C8: =IF(B8="","",IFERROR(INDEX(Patients!$B$2:$B$501,MATCH(B8,Patients!$A$2:$A$501,0))&"","")) | J8: =IF(D8="","",IFERROR(INDEX(Settings!$C$49:$C$54,MATCH(D8,Settings!$A$49:$A$54,0)),0)) | K8: =IF(J8="","",IF(G8="",J8,J8*(1-IF(H8="",Settings!$B$6,H8)))) | L8: =IF(OR(J8="",G8=""),"",J8-K8)
C9: =IF(B9="","",IFERROR(INDEX(Patients!$B$2:$B$501,MATCH(B9,Patients!$A$2:$A$501,0))&"","")) | J9: =IF(D9="","",IFERROR(INDEX(Settings!$C$49:$C$54,MATCH(D9,Settings!$A$49:$A$54,0)),0)) | K9: =IF(J9="","",IF(G9="",J9,J9*(1-IF(H9="",Settings!$B$6,H9)))) | L9: =IF(OR(J9="",G9=""),"",J9-K9)
C10: =IF(B10="","",IFERROR(INDEX(Patients!$B$2:$B$501,MATCH(B10,Patients!$A$2:$A$501,0))&"","")) | J10: =IF(D10="","",IFERROR(INDEX(Settings!$C$49:$C$54,MATCH(D10,Settings!$A$49:$A$54,0)),0)) | K10: =IF(J10="","",IF(G10="",J10,J10*(1-IF(H10="",Settings!$B$6,H10)))) | L10: =IF(OR(J10="",G10=""),"",J10-K10)
C11: =IF(B11="","",IFERROR(INDEX(Patients!$B$2:$B$501,MATCH(B11,Patients!$A$2:$A$501,0))&"","")) | J11: =IF(D11="","",IFERROR(INDEX(Settings!$C$49:$C$54,MATCH(D11,Settings!$A$49:$A$54,0)),0)) | K11: =IF(J11="","",IF(G11="",J11,J11*(1-IF(H11="",Settings!$B$6,H11)))) | L11: =IF(OR(J11="",G11=""),"",J11-K11)
C12: =IF(B12="","",IFERROR(INDEX(Patients!$B$2:$B$501,MATCH(B12,Patients!$A$2:$A$501,0))&"","")) | J12: =IF(D12="","",IFERROR(INDEX(Settings!$C$49:$C$54,MATCH(D12,Settings!$A$49:$A$54,0)),0)) | K12: =IF(J12="","",IF(G12="",J12,J12*(1-IF(H12="",Settings!$B$6,H12)))) | L12: =IF(OR(J12="",G12=""),"",J12-K12)
C13: =IF(B13="","",IFERROR(INDEX(Patients!$B$2:$B$501,MATCH(B13,Patients!$A$2:$A$501,0))&"","")) | J13: =IF(D13="","",IFERROR(INDEX(Settings!$C$49:$C$54,MATCH(D13,Settings!$A$49:$A$54,0)),0)) | K13: =IF(J13="","",IF(G13="",J13,J13*(1-IF(H13="",Settings!$B$6,H13)))) | L13: =IF(OR(J13="",G13=""),"",J13-K13)
C14: =IF(B14="","",IFERROR(INDEX(Patients!$B$2:$B$501,MATCH(B14,Patients!$A$2:$A$501,0))&"","")) | J14: =IF(D14="","",IFERROR(INDEX(Settings!$C$49:$C$54,MATCH(D14,Settings!$A$49:$A$54,0)),0)) | K14: =IF(J14="","",IF(G14="",J14,J14*(1-IF(H14="",Settings!$B$6,H14)))) | L14: =IF(OR(J14="",G14=""),"",J14-K14)
... C501: =IF(B501="","",IFERROR(INDEX(Patients!$B$2:$B$501,MATCH(B501,Patients!$A$2:$A$501,0))&"","")) | J501: =IF(D501="","",IFERROR(INDEX(Settings!$C$49:$C$54,MATCH(D501,Settings!$A$49:$A$54,0)),0)) | K501: =IF(J501="","",IF(G501="",J501,J501*(1-IF(H501="",Settings!$B$6,H501)))) | L501: =IF(OR(J501="",G501=""),"",J501-K501)

Sheet Purchases
A1: Invoice Date | B1: Vendor Name | C1: Invoice Number | D1: Product | E1: Quantity | F1: Batch | G1: Expiry | H1: Purchase Rate (₹) | I1: GST % | J1: Taxable Value (₹) | K1: GST Amount (₹) | L1: Line Total (₹)
A2: 46266 | B2: Example Pharma Distributors | C2: INV-0001 | D2: Mounjaro 5mg | E2: 2 | F2: B1234 | G2: 46539 | H2: 4000 | I2: 0.05 | J2: =IF(D2="","",E2*H2) -> 8000 | K2: =IF(D2="","",J2*I2) -> 400 | L2: =IF(D2="","",J2+K2) -> 8400
A3: 46266 | B3: Example Pharma Distributors | C3: INV-0001 | D3: Protein Sachets | E3: 100 | F3: P778 | G3: 46447 | H3: 60 | I3: 0.18 | J3: =IF(D3="","",E3*H3) -> 6000 | K3: =IF(D3="","",J3*I3) -> 1080 | L3: =IF(D3="","",J3+K3) -> 7080
J4: =IF(D4="","",E4*H4) | K4: =IF(D4="","",J4*I4) | L4: =IF(D4="","",J4+K4)
J5: =IF(D5="","",E5*H5) | K5: =IF(D5="","",J5*I5) | L5: =IF(D5="","",J5+K5)
J6: =IF(D6="","",E6*H6) | K6: =IF(D6="","",J6*I6) | L6: =IF(D6="","",J6+K6)
J7: =IF(D7="","",E7*H7) | K7: =IF(D7="","",J7*I7) | L7: =IF(D7="","",J7+K7)
J8: =IF(D8="","",E8*H8) | K8: =IF(D8="","",J8*I8) | L8: =IF(D8="","",J8+K8)
J9: =IF(D9="","",E9*H9) | K9: =IF(D9="","",J9*I9) | L9: =IF(D9="","",J9+K9)
J10: =IF(D10="","",E10*H10) | K10: =IF(D10="","",J10*I10) | L10: =IF(D10="","",J10+K10)
J11: =IF(D11="","",E11*H11) | K11: =IF(D11="","",J11*I11) | L11: =IF(D11="","",J11+K11)
J12: =IF(D12="","",E12*H12) | K12: =IF(D12="","",J12*I12) | L12: =IF(D12="","",J12+K12)
J13: =IF(D13="","",E13*H13) | K13: =IF(D13="","",J13*I13) | L13: =IF(D13="","",J13+K13)
J14: =IF(D14="","",E14*H14) | K14: =IF(D14="","",J14*I14) | L14: =IF(D14="","",J14+K14)
J15: =IF(D15="","",E15*H15) | K15: =IF(D15="","",J15*I15) | L15: =IF(D15="","",J15+K15)
... J501: =IF(D501="","",E501*H501) | K501: =IF(D501="","",J501*I501) | L501: =IF(D501="","",J501+K501)

Sheet Inventory
A1: Category | B1: Item | C1: Unit | D1: Opening Stock | E1: Purchased Stock | F1: Sold Stock | G1: Adjusted (+/−) | H1: Available Stock | I1: Low Stock At | J1: Status
A2: Injection | B2: Mounjaro 2.5mg | C2: pen | D2: 0 | E2: =IF(B2="","",SUMIFS(Purchases!$E$2:$E$501,Purchases!$D$2:$D$501,B2)) -> 0 | F2: =IF(B2="","",SUMIFS('Injection Sales'!$F$2:$F$501,'Injection Sales'!$E$2:$E$501,B2)+SUMIFS('Protein Sales'!$E$2:$E$501,'Protein Sales'!$D$2:$D$501,B2)) -> 0 | H2: =IF(B2="","",N(D2)+E2-F2+N(G2)) -> 0 | I2: 2 | J2: =IF(B2="","",IF(H2<=I2,"LOW","OK")) -> LOW
A3: Injection | B3: Mounjaro 5mg | C3: pen | D3: 0 | E3: =IF(B3="","",SUMIFS(Purchases!$E$2:$E$501,Purchases!$D$2:$D$501,B3)) -> 2 | F3: =IF(B3="","",SUMIFS('Injection Sales'!$F$2:$F$501,'Injection Sales'!$E$2:$E$501,B3)+SUMIFS('Protein Sales'!$E$2:$E$501,'Protein Sales'!$D$2:$D$501,B3)) -> 1 | H3: =IF(B3="","",N(D3)+E3-F3+N(G3)) -> 1 | I3: 2 | J3: =IF(B3="","",IF(H3<=I3,"LOW","OK")) -> LOW
A4: Injection | B4: Mounjaro 10mg | C4: pen | D4: 0 | E4: =IF(B4="","",SUMIFS(Purchases!$E$2:$E$501,Purchases!$D$2:$D$501,B4)) -> 0 | F4: =IF(B4="","",SUMIFS('Injection Sales'!$F$2:$F$501,'Injection Sales'!$E$2:$E$501,B4)+SUMIFS('Protein Sales'!$E$2:$E$501,'Protein Sales'!$D$2:$D$501,B4)) -> 0 | H4: =IF(B4="","",N(D4)+E4-F4+N(G4)) -> 0 | I4: 2 | J4: =IF(B4="","",IF(H4<=I4,"LOW","OK")) -> LOW
A5: Injection | B5: Mounjaro 15mg | C5: pen | D5: 0 | E5: =IF(B5="","",SUMIFS(Purchases!$E$2:$E$501,Purchases!$D$2:$D$501,B5)) -> 0 | F5: =IF(B5="","",SUMIFS('Injection Sales'!$F$2:$F$501,'Injection Sales'!$E$2:$E$501,B5)+SUMIFS('Protein Sales'!$E$2:$E$501,'Protein Sales'!$D$2:$D$501,B5)) -> 0 | H5: =IF(B5="","",N(D5)+E5-F5+N(G5)) -> 0 | I5: 2 | J5: =IF(B5="","",IF(H5<=I5,"LOW","OK")) -> LOW
A6: Injection | B6: Wegovy 0.25mg | C6: pen | D6: 0 | E6: =IF(B6="","",SUMIFS(Purchases!$E$2:$E$501,Purchases!$D$2:$D$501,B6)) -> 0 | F6: =IF(B6="","",SUMIFS('Injection Sales'!$F$2:$F$501,'Injection Sales'!$E$2:$E$501,B6)+SUMIFS('Protein Sales'!$E$2:$E$501,'Protein Sales'!$D$2:$D$501,B6)) -> 0 | H6: =IF(B6="","",N(D6)+E6-F6+N(G6)) -> 0 | I6: 2 | J6: =IF(B6="","",IF(H6<=I6,"LOW","OK")) -> LOW
A7: Injection | B7: Wegovy 1mg | C7: pen | D7: 0 | E7: =IF(B7="","",SUMIFS(Purchases!$E$2:$E$501,Purchases!$D$2:$D$501,B7)) -> 0 | F7: =IF(B7="","",SUMIFS('Injection Sales'!$F$2:$F$501,'Injection Sales'!$E$2:$E$501,B7)+SUMIFS('Protein Sales'!$E$2:$E$501,'Protein Sales'!$D$2:$D$501,B7)) -> 0 | H7: =IF(B7="","",N(D7)+E7-F7+N(G7)) -> 0 | I7: 2 | J7: =IF(B7="","",IF(H7<=I7,"LOW","OK")) -> LOW
A8: Injection | B8: Wegovy 2.4mg | C8: pen | D8: 0 | E8: =IF(B8="","",SUMIFS(Purchases!$E$2:$E$501,Purchases!$D$2:$D$501,B8)) -> 0 | F8: =IF(B8="","",SUMIFS('Injection Sales'!$F$2:$F$501,'Injection Sales'!$E$2:$E$501,B8)+SUMIFS('Protein Sales'!$E$2:$E$501,'Protein Sales'!$D$2:$D$501,B8)) -> 0 | H8: =IF(B8="","",N(D8)+E8-F8+N(G8)) -> 0 | I8: 2 | J8: =IF(B8="","",IF(H8<=I8,"LOW","OK")) -> LOW
A9: Injection | B9: Ozempic 0.25mg | C9: pen | D9: 0 | E9: =IF(B9="","",SUMIFS(Purchases!$E$2:$E$501,Purchases!$D$2:$D$501,B9)) -> 0 | F9: =IF(B9="","",SUMIFS('Injection Sales'!$F$2:$F$501,'Injection Sales'!$E$2:$E$501,B9)+SUMIFS('Protein Sales'!$E$2:$E$501,'Protein Sales'!$D$2:$D$501,B9)) -> 0 | H9: =IF(B9="","",N(D9)+E9-F9+N(G9)) -> 0 | I9: 2 | J9: =IF(B9="","",IF(H9<=I9,"LOW","OK")) -> LOW
A10: Injection | B10: Ozempic 1mg | C10: pen | D10: 0 | E10: =IF(B10="","",SUMIFS(Purchases!$E$2:$E$501,Purchases!$D$2:$D$501,B10)) -> 0 | F10: =IF(B10="","",SUMIFS('Injection Sales'!$F$2:$F$501,'Injection Sales'!$E$2:$E$501,B10)+SUMIFS('Protein Sales'!$E$2:$E$501,'Protein Sales'!$D$2:$D$501,B10)) -> 0 | H10: =IF(B10="","",N(D10)+E10-F10+N(G10)) -> 0 | I10: 2 | J10: =IF(B10="","",IF(H10<=I10,"LOW","OK")) -> LOW
A11: Protein | B11: Protein Sachets | C11: sachet | D11: 0 | E11: =IF(B11="","",SUMIFS(Purchases!$E$2:$E$501,Purchases!$D$2:$D$501,B11)) -> 100 | F11: =IF(B11="","",SUMIFS('Injection Sales'!$F$2:$F$501,'Injection Sales'!$E$2:$E$501,B11)+SUMIFS('Protein Sales'!$E$2:$E$501,'Protein Sales'!$D$2:$D$501,B11)) -> 30 | H11: =IF(B11="","",N(D11)+E11-F11+N(G11)) -> 70 | I11: 20 | J11: =IF(B11="","",IF(H11<=I11,"LOW","OK")) -> OK
A12: Needles | B12: Needles | C12: pcs | D12: 0 | E12: =IF(B12="","",SUMIFS(Purchases!$E$2:$E$501,Purchases!$D$2:$D$501,B12)) -> 0 | F12: =IF(B12="","",SUMIFS('Injection Sales'!$F$2:$F$501,'Injection Sales'!$E$2:$E$501,B12)+SUMIFS('Protein Sales'!$E$2:$E$501,'Protein Sales'!$D$2:$D$501,B12)) -> 0 | H12: =IF(B12="","",N(D12)+E12-F12+N(G12)) -> 0 | I12: 20 | J12: =IF(B12="","",IF(H12<=I12,"LOW","OK")) -> LOW
A13: Alcohol Swabs | B13: Alcohol Swabs | C13: pcs | D13: 0 | E13: =IF(B13="","",SUMIFS(Purchases!$E$2:$E$501,Purchases!$D$2:$D$501,B13)) -> 0 | F13: =IF(B13="","",SUMIFS('Injection Sales'!$F$2:$F$501,'Injection Sales'!$E$2:$E$501,B13)+SUMIFS('Protein Sales'!$E$2:$E$501,'Protein Sales'!$D$2:$D$501,B13)) -> 0 | H13: =IF(B13="","",N(D13)+E13-F13+N(G13)) -> 0 | I13: 20 | J13: =IF(B13="","",IF(H13<=I13,"LOW","OK")) -> LOW
... A16: Travel Bags | B16: Travel Bags | C16: pcs | D16: 0 | E16: =IF(B16="","",SUMIFS(Purchases!$E$2:$E$501,Purchases!$D$2:$D$501,B16)) -> 0 | F16: =IF(B16="","",SUMIFS('Injection Sales'!$F$2:$F$501,'Injection Sales'!$E$2:$E$501,B16)+SUMIFS('Protein Sales'!$E$2:$E$501,'Protein Sales'!$D$2:$D$501,B16)) -> 0 | H16: =IF(B16="","",N(D16)+E16-F16+N(G16)) -> 0 | I16: 20 | J16: =IF(B16="","",IF(H16<=I16,"LOW","OK")) -> LOW
E17: =IF(B17="","",SUMIFS(Purchases!$E$2:$E$501,Purchases!$D$2:$D$501,B17)) | F17: =IF(B17="","",SUMIFS('Injection Sales'!$F$2:$F$501,'Injection Sales'!$E$2:$E$501,B17)+SUMIFS('Protein Sales'!$E$2:$E$501,'Protein Sales'!$D$2:$D$501,B17)) | H17: =IF(B17="","",N(D17)+E17-F17+N(G17)) | J17: =IF(B17="","",IF(H17<=I17,"LOW","OK"))
E18: =IF(B18="","",SUMIFS(Purchases!$E$2:$E$501,Purchases!$D$2:$D$501,B18)) | F18: =IF(B18="","",SUMIFS('Injection Sales'!$F$2:$F$501,'Injection Sales'!$E$2:$E$501,B18)+SUMIFS('Protein Sales'!$E$2:$E$501,'Protein Sales'!$D$2:$D$501,B18)) | H18: =IF(B18="","",N(D18)+E18-F18+N(G18)) | J18: =IF(B18="","",IF(H18<=I18,"LOW","OK"))
E19: =IF(B19="","",SUMIFS(Purchases!$E$2:$E$501,Purchases!$D$2:$D$501,B19)) | F19: =IF(B19="","",SUMIFS('Injection Sales'!$F$2:$F$501,'Injection Sales'!$E$2:$E$501,B19)+SUMIFS('Protein Sales'!$E$2:$E$501,'Protein Sales'!$D$2:$D$501,B19)) | H19: =IF(B19="","",N(D19)+E19-F19+N(G19)) | J19: =IF(B19="","",IF(H19<=I19,"LOW","OK"))
E20: =IF(B20="","",SUMIFS(Purchases!$E$2:$E$501,Purchases!$D$2:$D$501,B20)) | F20: =IF(B20="","",SUMIFS('Injection Sales'!$F$2:$F$501,'Injection Sales'!$E$2:$E$501,B20)+SUMIFS('Protein Sales'!$E$2:$E$501,'Protein Sales'!$D$2:$D$501,B20)) | H20: =IF(B20="","",N(D20)+E20-F20+N(G20)) | J20: =IF(B20="","",IF(H20<=I20,"LOW","OK"))
E21: =IF(B21="","",SUMIFS(Purchases!$E$2:$E$501,Purchases!$D$2:$D$501,B21)) | F21: =IF(B21="","",SUMIFS('Injection Sales'!$F$2:$F$501,'Injection Sales'!$E$2:$E$501,B21)+SUMIFS('Protein Sales'!$E$2:$E$501,'Protein Sales'!$D$2:$D$501,B21)) | H21: =IF(B21="","",N(D21)+E21-F21+N(G21)) | J21: =IF(B21="","",IF(H21<=I21,"LOW","OK"))
E22: =IF(B22="","",SUMIFS(Purchases!$E$2:$E$501,Purchases!$D$2:$D$501,B22)) | F22: =IF(B22="","",SUMIFS('Injection Sales'!$F$2:$F$501,'Injection Sales'!$E$2:$E$501,B22)+SUMIFS('Protein Sales'!$E$2:$E$501,'Protein Sales'!$D$2:$D$501,B22)) | H22: =IF(B22="","",N(D22)+E22-F22+N(G22)) | J22: =IF(B22="","",IF(H22<=I22,"LOW","OK"))
E23: =IF(B23="","",SUMIFS(Purchases!$E$2:$E$501,Purchases!$D$2:$D$501,B23)) | F23: =IF(B23="","",SUMIFS('Injection Sales'!$F$2:$F$501,'Injection Sales'!$E$2:$E$501,B23)+SUMIFS('Protein Sales'!$E$2:$E$501,'Protein Sales'!$D$2:$D$501,B23)) | H23: =IF(B23="","",N(D23)+E23-F23+N(G23)) | J23: =IF(B23="","",IF(H23<=I23,"LOW","OK"))
E24: =IF(B24="","",SUMIFS(Purchases!$E$2:$E$501,Purchases!$D$2:$D$501,B24)) | F24: =IF(B24="","",SUMIFS('Injection Sales'!$F$2:$F$501,'Injection Sales'!$E$2:$E$501,B24)+SUMIFS('Protein Sales'!$E$2:$E$501,'Protein Sales'!$D$2:$D$501,B24)) | H24: =IF(B24="","",N(D24)+E24-F24+N(G24)) | J24: =IF(B24="","",IF(H24<=I24,"LOW","OK"))
E25: =IF(B25="","",SUMIFS(Purchases!$E$2:$E$501,Purchases!$D$2:$D$501,B25)) | F25: =IF(B25="","",SUMIFS('Injection Sales'!$F$2:$F$501,'Injection Sales'!$E$2:$E$501,B25)+SUMIFS('Protein Sales'!$E$2:$E$501,'Protein Sales'!$D$2:$D$501,B25)) | H25: =IF(B25="","",N(D25)+E25-F25+N(G25)) | J25: =IF(B25="","",IF(H25<=I25,"LOW","OK"))
E26: =IF(B26="","",SUMIFS(Purchases!$E$2:$E$501,Purchases!$D$2:$D$501,B26)) | F26: =IF(B26="","",SUMIFS('Injection Sales'!$F$2:$F$501,'Injection Sales'!$E$2:$E$501,B26)+SUMIFS('Protein Sales'!$E$2:$E$501,'Protein Sales'!$D$2:$D$501,B26)) | H26: =IF(B26="","",N(D26)+E26-F26+N(G26)) | J26: =IF(B26="","",IF(H26<=I26,"LOW","OK"))
E27: =IF(B27="","",SUMIFS(Purchases!$E$2:$E$501,Purchases!$D$2:$D$501,B27)) | F27: =IF(B27="","",SUMIFS('Injection Sales'!$F$2:$F$501,'Injection Sales'!$E$2:$E$501,B27)+SUMIFS('Protein Sales'!$E$2:$E$501,'Protein Sales'!$D$2:$D$501,B27)) | H27: =IF(B27="","",N(D27)+E27-F27+N(G27)) | J27: =IF(B27="","",IF(H27<=I27,"LOW","OK"))
E28: =IF(B28="","",SUMIFS(Purchases!$E$2:$E$501,Purchases!$D$2:$D$501,B28)) | F28: =IF(B28="","",SUMIFS('Injection Sales'!$F$2:$F$501,'Injection Sales'!$E$2:$E$501,B28)+SUMIFS('Protein Sales'!$E$2:$E$501,'Protein Sales'!$D$2:$D$501,B28)) | H28: =IF(B28="","",N(D28)+E28-F28+N(G28)) | J28: =IF(B28="","",IF(H28<=I28,"LOW","OK"))
... E101: =IF(B101="","",SUMIFS(Purchases!$E$2:$E$501,Purchases!$D$2:$D$501,B101)) | F101: =IF(B101="","",SUMIFS('Injection Sales'!$F$2:$F$501,'Injection Sales'!$E$2:$E$501,B101)+SUMIFS('Protein Sales'!$E$2:$E$501,'Protein Sales'!$D$2:$D$501,B101)) | H101: =IF(B101="","",N(D101)+E101-F101+N(G101)) | J101: =IF(B101="","",IF(H101<=I101,"LOW","OK"))

Sheet Team
A1: Name | B1: Designation | C1: Mobile | D1: Salary (₹/month) | E1: Incentive Status | F1: Joining Date | G1: Status
A2: Murshida | B2: Counsellor | C2: 9876543210 | D2: 25000 | E2: On | F2: 46023 | G2: Active

Sheet Incentives
A1: Incentive summary for the Dashboard period
A2: From | B2: =Dashboard!$C$4 -> 46266 | C2: To | D2: =Dashboard!$C$5 -> 46295
A4: Team Member | B4: Injection Incentive (₹) | C4: Protein Incentive (₹) | D4: Diet Support Incentive (₹) | E4: Total Incentive (₹) | F4: Incentive Status
A5: =IF(Team!A2="","",Team!A2) -> Murshida | B5: =IF(A5="","",IF(F5="Off",0,SUMIFS('Injection Sales'!$M$2:$M$501,'Injection Sales'!$H$2:$H$501,$A5,'Injection Sales'!$A$2:$A$501,">="&$B$2,'Injection Sales'!$A$2:$A$501,"<="&$D$2)+SUMIFS('Injection Sales'!$N$2:$N$501,'Injection Sales'!$I$2:$I$501,$A5,'Injection Sales'!$A$2:$A$501,">="&$B$2,'Injection Sales'!$A$2:$A$501,"<="&$D$2))) -> 1000 | C5: =IF(A5="","",IF(F5="Off",0,SUMIFS('Protein Sales'!$K$2:$K$501,'Protein Sales'!$G$2:$G$501,$A5,'Protein Sales'!$A$2:$A$501,">="&$B$2,'Protein Sales'!$A$2:$A$501,"<="&$D$2)+SUMIFS('Protein Sales'!$L$2:$L$501,'Protein Sales'!$H$2:$H$501,$A5,'Protein Sales'!$A$2:$A$501,">="&$B$2,'Protein Sales'!$A$2:$A$501,"<="&$D$2))) -> 500 | D5: =IF(A5="","",IF(F5="Off",0,SUMIFS('Diet Support'!$K$2:$K$501,'Diet Support'!$F$2:$F$501,$A5,'Diet Support'!$A$2:$A$501,">="&$B$2,'Diet Support'!$A$2:$A$501,"<="&$D$2)+SUMIFS('Diet Support'!$L$2:$L$501,'Diet Support'!$G$2:$G$501,$A5,'Diet Support'!$A$2:$A$501,">="&$B$2,'Diet Support'!$A$2:$A$501,"<="&$D$2))) -> 2000 | E5: =IF(A5="","",SUM(B5:D5)) -> 3500 | F5: =IF(A5="","",IF(Team!E2="","On",Team!E2)) -> On
